Workbook
Name __xlnm._FilterDatabase_1: #REF!

Sheet FUNCLOC
A1: id | B1: tag_name | C1: created_at
A2: FP-01-SP1-CPO-T002-P006 | B2: SP1.CP.C2/P1/M | C2: 45251.353
A3: FP-01-SP1-CPO-T007-P203 | B3: SP1.CP.C6/P3/M | C3: 45251.353
A4: FP-01-SP1-CPO-T007-P013 | B4: SP1.CP.C6/P2/M | C4: 45251.354
A5: FP-01-SP1-CPO-DKC2 | B5: SP1.CP.DKC2/M | C5: 45251.354
A6: FP-01-SP1-CPO-DKC2-P018 | B6: SP1.CP.DKC2/P1 | C6: 45251.354
A7: FP-01-SP1-CPO-DKC2-P019 | B7: SP1.CP.DKC2/P2 | C7: 45251.354
A8: FP-01-SP1-CPO-SR01 | B8: SP1.CP.PS(C)1/M | C8: 45251.354
A9: FP-01-SP1-CPO-SR02 | B9: SP1.CP.JNS1/M | C9: 45251.354
A10: FP-01-SP1-CPO-SR04 | B10: SP1.CP.PS(F)1/M | C10: 45251.354
A11: FP-01-SP1-CPO-SR05 | B11: SP1.CP.PS(F)2/M | C11: 45251.354
A12: FP-01-SP1-CPO-SR06 | B12: SP1.CP.PS(F)3/M | C12: 45251.354
A13: FP-01-SP1-CPO-T001-P004 | B13: SP1.CP.C1.P1/M | C13: 45251.354
... A15: FP-01-SP1-CPO-T005-P009 | B15: SP1.CP.T3/P1/M | C15: 45251.354
B16: SP1.CP.T3/P2/M | C16: 45251.354
A17: FP-01-SP1-CPO-T006-A002 | B17: SP1.CP.C4/AGT/M | C17: 45251.354
A18: FP-01-SP1-CPO-T006-P011 | B18: SP1.CP.C4/P1/M | C18: 45251.354
A19: FP-01-SP1-CPO-T007-P012 | B19: SP1.CP.C6/P1/M | C19: 45251.354
A20: FP-01-SP1-CPO-T008-P014 | B20: SP1.CP.C7/P1/M | C20: 45251.354
A21: FP-01-SP1-CPO-T009-P015 | B21: SP1.CP.C8/P1/M | C21: 45251.354
A22: FP-01-SP1-CPO-T010-P016 | B22: SP1.CP.C17/P1/M | C22: 45251.354
A23: FP-01-SP1-CPO-T011-P020 | B23: SP1.CP.T8/P1/M | C23: 45251.354
B24: SP1.CP.C10/P1/M | C24: 45251.354
A25: FP-01-SP1-CPO-T013-P022 | B25: SP1.CP.C11/P1/M | C25: 45251.354
A26: FP-01-SP1-CPO-T014-P023 | B26: SP1.CP.C12/P1/M | C26: 45251.354
B27: SP1.CP.C13/P2/M | C27: 45251.354
B28: SP1.CP.C14/AGT/M | C28: 45251.354
A29: FP-01-SP1-CPO-T016-P027 | B29: SP1.CP.C14/P1/M | C29: 45251.354
A30: FP-01-SP1-CPO-T017-A004 | B30: SP1.CP.C5/AGT1/M | C30: 45251.354
A31: FP-01-SP1-CPO-T017-A005 | B31: SP1.CP.C5/AGT2/M | C31: 45251.354
A32: FP-01-SP1-CPO-T017-P028 | B32: SP1.CP.C5/P1/M | C32: 45251.354
A33: FP-01-SP1-CPO-T018-A006 | B33: SP1.CP.C5A/AGT1/M | C33: 45251.354
A34: FP-01-SP1-CPO-T018-A007 | B34: SP1.CP.C5A/AGT2/M | C34: 45251.354
A35: FP-01-SP1-CPO-T019-P030 | B35: SP1.CP.C16/P1/M | C35: 45251.354
A36: FP-01-SP1-CPO-T020-A008 | B36: SP1.CP.C18/AGT/M | C36: 45251.354
A37: FP-01-SP1-CPO-T022-P033 | B37: SP1.CP.T7/P1/M | C37: 45251.354
B38: SP1.CP.C15/P3/M | C38: 45251.354
B39: SP1.CP.T5/P1/M | C39: 45251.354
A40: FP-01-SP1-CLD-TH21 | B40: SP1.CL.THK4/GB/M | C40: 45251.354
A41: FP-01-CH7-STA-T119-A036 | B41: CH7.7CAS02/AGT/M | C41: 45251.354
...

Sheet EMO
A1: id | B1: status | C1: funcloc | D1: sort_field | E1: material_number | F1: equipment_description | G1: unique_id | H1: qr_code_link | I1: created_at
A2: EMO000576 | B2: Installed | C2: FP-01-SP1-CPO-T002-P006 | D2: SP1.CP.C2/P1/M | E2: 10010924 | F2: AC MOTOR;380V,50Hz,15kW,4P,160L,B3 | G2: 20 | H2: https://www.safesave.info/MIC.php?id=Fajar-MotorList20 | I2: 45251.353
A3: EMO000349 | B3: Installed | C3: FP-01-SP1-CPO-T007-P203 | D3: SP1.CP.C6/P3/M | F3: AC MOTOR;380V,50Hz,45kW,4P,225M,B3 | G3: 21 | H3: https://www.safesave.info/MIC.php?id=Fajar-MotorList21 | I3: 45251.353
A4: EMO000407 | B4: Installed | C4: FP-01-SP1-CPO-T007-P013 | D4: SP1.CP.C6/P2/M | E4: 10010560 | F4: AC MOTOR;380V,50Hz,30kW,4P,200M,B3 | G4: 22 | H4: https://www.safesave.info/MIC.php?id=Fajar-MotorList22 | I4: 45251.354
A5: EMO000436 | B5: Installed | C5: FP-01-SP1-CPO-DKC2 | D5: SP1.CP.DKC2/M | F5: AC MOTOR;380V,50Hz,0.11kW,4P,V | G5: 23 | H5: https://www.safesave.info/MIC.php?id=Fajar-MotorList23 | I5: 45251.354
A6: EMO000435 | B6: Installed | C6: FP-01-SP1-CPO-DKC2-P018 | D6: SP1.CP.DKC2/P1 | E6: 10024161 | F6: AC MOTOR;380V,50Hz,75kW,6P,280M,B3 | G6: 24 | H6: https://www.safesave.info/MIC.php?id=Fajar-MotorList24 | I6: 45251.354
A7: EMO000438 | B7: Installed | C7: FP-01-SP1-CPO-DKC2-P019 | D7: SP1.CP.DKC2/P2 | E7: 10024161 | F7: AC MOTOR;380V,50Hz,75kW,6P,280M,B3 | G7: 25 | H7: https://www.safesave.info/MIC.php?id=Fajar-MotorList25 | I7: 45251.354
A8: EMO002909 | B8: Installed | C8: FP-01-SP1-CPO-SR01 | D8: SP1.CP.PS(C)1/M | E8: 10010666 | F8: AC MOTOR;380V,50Hz,55kW,6P,280SC,V5 | G8: 26 | H8: https://www.safesave.info/MIC.php?id=Fajar-MotorList26 | I8: 45251.354
A9: EMO000443 | B9: Installed | C9: FP-01-SP1-CPO-SR02 | D9: SP1.CP.JNS1/M | F9: AC MOTOR;380V,50Hz,3.70kW,4P,112 | G9: 27 | H9: https://www.safesave.info/MIC.php?id=Fajar-MotorList27 | I9: 45251.354
A10: EMO000445 | B10: Installed | C10: FP-01-SP1-CPO-SR04 | D10: SP1.CP.PS(F)1/M | F10: AC MOTOR;380V,50Hz,55kW,8P,315,V | G10: 28 | H10: https://www.safesave.info/MIC.php?id=Fajar-MotorList28 | I10: 45251.354
A11: EMO000446 | B11: Installed | C11: FP-01-SP1-CPO-SR05 | D11: SP1.CP.PS(F)2/M | F11: AC MOTOR;380V,50Hz,37kW,6P,250,V | G11: 29 | H11: https://www.safesave.info/MIC.php?id=Fajar-MotorList29 | I11: 45251.354
A12: EMO000447 | B12: Installed | C12: FP-01-SP1-CPO-SR06 | D12: SP1.CP.PS(F)3/M | F12: AC MOTOR;380V,50Hz,30kW,4P,200L,B | G12: 30 | H12: https://www.safesave.info/MIC.php?id=Fajar-MotorList30 | I12: 45251.354
A13: EMO000382 | B13: Installed | C13: FP-01-SP1-CPO-T001-P004 | D13: SP1.CP.C1.P1/M | E13: 10010891 | F13: AC MOTOR;380V,50Hz,37kW,4P,225S,B3 | G13: 31 | H13: https://www.safesave.info/MIC.php?id=Fajar-MotorList31 | I13: 45251.354
A14: EMO000452 | B14: Installed | C14: FP-01-SP1-MXW-T065-P086 | D14: SP1.MW.C1/P/M | E14: 10010668 | F14: AC MOTOR;380V,50Hz,75kW,4P,250M,B3 | G14: 32 | H14: https://www.safesave.info/MIC.php?id=Fajar-MotorList32 | I14: 45251.354
A15: EMO000453 | B15: Installed | C15: FP-01-SP1-CPO-T005-P009 | D15: SP1.CP.T3/P1/M | F15: AC MOTOR;380V,50Hz,22kW,4P,180L,B3 | G15: 33 | H15: https://www.safesave.info/MIC.php?id=Fajar-MotorList33 | I15: 45251.354
A16: EMO000454 | B16: Available | E16: 10010883 | F16: AC MOTOR;380V,50Hz,18.5kW,4P,180M,B3 | G16: 34 | H16: https://www.safesave.info/MIC.php?id=Fajar-MotorList34 | I16: 45251.354
A17: EMO000455 | B17: Installed | C17: FP-01-SP1-CPO-T006-A002 | D17: SP1.CP.C4/AGT/M | F17: AC MOTOR;380V,50Hz,15kW,6P,180L,B3 | G17: 35 | H17: https://www.safesave.info/MIC.php?id=Fajar-MotorList35 | I17: 45251.354
A18: EMO000456 | B18: Installed | C18: FP-01-SP1-CPO-T006-P011 | D18: SP1.CP.C4/P1/M | F18: AC MOTOR;380V,50Hz,37kW,4P,225S,B3 | G18: 36 | H18: https://www.safesave.info/MIC.php?id=Fajar-MotorList36 | I18: 45251.354
A19: EMO000458 | B19: Installed | C19: FP-01-SP1-CPO-T007-P012 | D19: SP1.CP.C6/P1/M | F19: AC MOTOR;380V,50Hz,30kW,4P,200L,B3 | G19: 37 | H19: https://www.safesave.info/MIC.php?id=Fajar-MotorList37 | I19: 45251.354
A20: EMO000459 | B20: Installed | C20: FP-01-SP1-CPO-T008-P014 | D20: SP1.CP.C7/P1/M | E20: 10010924 | F20: AC MOTOR;380V,50Hz,15kW,4P,160L,B3 | G20: 38 | H20: https://www.safesave.info/MIC.php?id=Fajar-MotorList38 | I20: 45251.354
A21: EMO000460 | B21: Installed | C21: FP-01-SP1-CPO-T009-P015 | D21: SP1.CP.C8/P1/M | E21: 10010924 | F21: AC MOTOR;380V,50Hz,15kW,4P,160L,B3 | G21: 39 | H21: https://www.safesave.info/MIC.php?id=Fajar-MotorList39 | I21: 45251.354
A22: EMO003501 | B22: Installed | C22: FP-01-SP1-CPO-T010-P016 | D22: SP1.CP.C17/P1/M | E22: 10025942 | F22: AC MOTOR;380V,50Hz,90kW,6P,315S,B3 | G22: 40 | H22: https://www.safesave.info/MIC.php?id=Fajar-MotorList40 | I22: 45251.354
A23: EMO000462 | B23: Installed | C23: FP-01-SP1-CPO-T011-P020 | D23: SP1.CP.T8/P1/M | E23: 10020913 | F23: AC MOTOR;380V,50Hz,22kW,4P,180L,B3 | G23: 41 | H23: https://www.safesave.info/MIC.php?id=Fajar-MotorList41 | I23: 45251.354
A24: EMO002103 | B24: Available | E24: 10010927 | F24: AC MOTOR;380V,50Hz,75kW,4P,280S,B3 | G24: 42 | H24: https://www.safesave.info/MIC.php?id=Fajar-MotorList42 | I24: 45251.354
A25: EMO000464 | B25: Installed | C25: FP-01-SP1-CPO-T013-P022 | D25: SP1.CP.C11/P1/M | F25: AC MOTOR;380V,50Hz,18.5kW,4P,160L,B3 | G25: 43 | H25: https://www.safesave.info/MIC.php?id=Fajar-MotorList43 | I25: 45251.354
A26: EMO001060 | B26: Installed | C26: FP-01-SP1-CPO-T014-P023 | D26: SP1.CP.C12/P1/M | E26: 10020888 | F26: AC MOTOR;380V,50Hz,15kW,4P,160L,B3 | G26: 44 | H26: https://www.safesave.info/MIC.php?id=Fajar-MotorList44 | I26: 45251.354
A27: EMO000467 | B27: Available | E27: 10010924 | F27: AC MOTOR;380V,50Hz,15kW,4P,160L,B3 | G27: 45 | H27: https://www.safesave.info/MIC.php?id=Fajar-MotorList45 | I27: 45251.354
A28: EMO000468 | B28: Available | E28: 10020927 | F28: AC MOTOR;380V,50Hz,22kW,6P,280S,B3 | G28: 46 | H28: https://www.safesave.info/MIC.php?id=Fajar-MotorList46 | I28: 45251.354
A29: EMO000469 | B29: Installed | C29: FP-01-SP1-CPO-T016-P027 | D29: SP1.CP.C14/P1/M | F29: AC MOTOR;380V,50Hz,37kW,4P,225S,B3 | G29: 47 | H29: https://www.safesave.info/MIC.php?id=Fajar-MotorList47 | I29: 45251.354
A30: EMO000470 | B30: Installed | C30: FP-01-SP1-CPO-T017-A004 | D30: SP1.CP.C5/AGT1/M | F30: AC MOTOR;380V,50Hz,55kW,6P,280SC,B3 | G30: 48 | H30: https://www.safesave.info/MIC.php?id=Fajar-MotorList48 | I30: 45251.354
A31: EMO000471 | B31: Installed | C31: FP-01-SP1-CPO-T017-A005 | D31: SP1.CP.C5/AGT2/M | F31: AC MOTOR;380V,50Hz,55kW,6P,280SC,B3 | G31: 49 | H31: https://www.safesave.info/MIC.php?id=Fajar-MotorList49 | I31: 45251.354
A32: EMO000472 | B32: Installed | C32: FP-01-SP1-CPO-T017-P028 | D32: SP1.CP.C5/P1/M | F32: AC MOTOR;380V,50Hz,37kW,4P,225S,B3 | G32: 50 | H32: https://www.safesave.info/MIC.php?id=Fajar-MotorList50 | I32: 45251.354
A33: EMO002949 | B33: Installed | C33: FP-01-SP1-CPO-T018-A006 | D33: SP1.CP.C5A/AGT1/M | E33: 10010901 | F33: AC MOTOR;380V,50Hz,45kW,6P,280S,B3 | G33: 51 | H33: https://www.safesave.info/MIC.php?id=Fajar-MotorList51 | I33: 45251.354
A34: EMO000474 | B34: Installed | C34: FP-01-SP1-CPO-T018-A007 | D34: SP1.CP.C5A/AGT2/M | F34: AC MOTOR;380V,50Hz,55kW,6P,280S,B3 | G34: 52 | H34: https://www.safesave.info/MIC.php?id=Fajar-MotorList52 | I34: 45251.354
A35: EMO000476 | B35: Installed | C35: FP-01-SP1-CPO-T019-P030 | D35: SP1.CP.C16/P1/M | E35: 10020913 | F35: AC MOTOR;380V,50Hz,22kW,4P,180L,B3 | G35: 53 | H35: https://www.safesave.info/MIC.php?id=Fajar-MotorList53 | I35: 45251.354
A36: EMO000545 | B36: Installed | C36: FP-01-SP1-CPO-T020-A008 | D36: SP1.CP.C18/AGT/M | E36: 10011106 | F36: AC MOTOR;380V,50Hz,22kW,6P,200L,B3 | G36: 54 | H36: https://www.safesave.info/MIC.php?id=Fajar-MotorList54 | I36: 45251.354
A37: EMO000481 | B37: Installed | C37: FP-01-SP1-CPO-T022-P033 | D37: SP1.CP.T7/P1/M | F37: AC MOTOR;380V,50Hz,37kW,4P,225S,B3 | G37: 55 | H37: https://www.safesave.info/MIC.php?id=Fajar-MotorList55 | I37: 45251.354
A38: EMO000105 | B38: Available | E38: 10010923 | F38: AC MOTOR;380V,50Hz,7.5kW,4P,132M,B3 | G38: 56 | H38: https://www.safesave.info/MIC.php?id=Fajar-MotorList56 | I38: 45251.354
A39: EMO000487 | B39: Available | E39: 10010819 | F39: AC MOTOR;380V,50Hz,7.5kW,4P,132M,B3 | G39: 57 | H39: https://www.safesave.info/MIC.php?id=Fajar-MotorList57 | I39: 45251.354
A40: EMO003727 | B40: Installed | C40: FP-01-SP1-CLD-TH21 | D40: SP1.CL.THK4/GB/M | E40: 10020936 | F40: AC MOTOR;380V,50Hz,7.5kW,4P,132S,V1 | G40: 58 | H40: https://www.safesave.info/MIC.php?id=Fajar-MotorList58 | I40: 45251.354
...

Sheet EMO_DETAILS
A1: emo_detail | B1: manufacture | C1: serial_number | D1: type | E1: power_rate | F1: power_unit | G1: voltage | H1: current_nominal | I1: frequency | J1: pole | K1: rpm | L1: bearing_de | M1: bearing_nde | N1: frame_type | O1: shaft_diameter | P1: phase_supply | Q1: cos_phi | R1: efficiency | S1: ip_rating | T1: insulation_class | U1: duty | V1: connection_type | W1: nipple_grease | X1: greasing_type | Y1: greasing_qty_de | Z1: greasing_qty_nde | AA1: length | AB1: width | AC1: height | AD1: weight | AE1: cooling_fan | AF1: mounting
A2: =(EMO!A2) -> EMO000576 | B2: ABB | D2: MBT | E2: 15 | F2: kW | G2: 380 | H2: 30 | I2: 50 | J2: 4 | K2: 1470 | L2: -- | M2: -- | N2: 160L | O2: 42 | P2: 3 | S2: 55 | T2: F | V2: Delta | W2: Not Available | AA2: 254 | AB2: 254 | AC2: 160 | AE2: Internal | AF2: Horizontal
A3: =(EMO!A3) -> EMO000349 | B3: ABB | D3: MBT | E3: 45 | F3: kW | G3: 380 | H3: 88 | I3: 50 | J3: 4 | K3: 1475 | N3: 225M | O3: 60 | P3: 3 | S3: 55 | T3: F | V3: Delta | W3: Available | AA3: 286/311 | AB3: 356 | AC3: 225 | AE3: Internal | AF3: Horizontal
A4: =(EMO!A4) -> EMO000407 | B4: TECO | C4: 75B23000 | D4: AEEBKB | E4: 30 | F4: kW | G4: 380 | H4: 57 | I4: 50 | J4: 4 | K4: 1480 | L4: 6312 | M4: 6212 | N4: 200LA | O4: 55 | P4: 3 | S4: 55 | T4: F | V4: Delta | W4: Available | AA4: 305 | AB4: 318 | AC4: 200 | AE4: Internal | AF4: Horizontal
A5: =(EMO!A5) -> EMO000436 | B5: EBER HARD BAUER | C5: 1895530 | D5: SG335 | E5: 0.11 | F5: kW | G5: 380 | H5: 0.55 | I5: 50 | J5: 4 | K5: 1390 | P5: 3 | T5: F | W5: Not Available | AE5: Internal | AF5: Vertical
A6: =(EMO!A6) -> EMO000435 | B6: ABB | C6: 3219691 | D6: HXR | E6: 75 | F6: kW | G6: 380 | H6: 144 | I6: 50 | J6: 6 | K6: 988 | L6: 6316 | M6: 6315 | N6: 280M | P6: 3 | S6: 55 | T6: F | V6: Delta | W6: Available | AC6: 280 | AE6: Internal | AF6: Horizontal
A7: =(EMO!A7) -> EMO000438 | B7: ABB | C7: 3219690 | D7: HXR | E7: 75 | F7: kW | G7: 380 | H7: 144 | I7: 50 | J7: 6 | K7: 988 | L7: 6316 | M7: 6315 | N7: 280M | P7: 3 | S7: 55 | T7: F | V7: Delta | W7: Available | AC7: 280 | AE7: Internal | AF7: Horizontal
A8: =(EMO!A8) -> EMO002909 | B8: TECO | C8: P9624252 | D8: AEBB | E8: 55 | F8: kW | G8: 380 | H8: 108 | I8: 50 | J8: 6 | K8: 970 | L8: NU318 | M8: 6316 | N8: 280SC | O8: 80 | P8: 3 | S8: 55 | T8: F | V8: Delta | W8: Available | AA8: 368 | AB8: 457 | AC8: 280 | AE8: Internal | AF8: Horizontal
A9: =(EMO!A9) -> EMO000443 | B9: TECO | C9: K9500353-200 | D9: AEEBAC | E9: 3.7 | F9: kW | G9: 380 | H9: 8.41 | I9: 50 | J9: 4 | K9: 1440 | L9: 6306 | M9: 6306 | N9: 112 | O9: 28 | P9: 3 | S9: 55 | T9: F | V9: Star | W9: Not Available | AA9: 140 | AB9: 190 | AC9: 112 | AE9: Internal | AF9: Horizontal
A10: =(EMO!A10) -> EMO000445 | B10: ABB | C10: 3180225 | D10: HXR | E10: 55 | F10: kW | G10: 380 | H10: 112 | I10: 50 | J10: 8 | K10: 740 | L10: 6319 | M10: 6316 | N10: 315 | P10: 3 | S10: 55 | T10: F | V10: Delta | W10: Available | AE10: Internal | AF10: Horizontal
A11: =(EMO!A11) -> EMO000446 | B11: ABB | C11: 3180262 | D11: HXR | E11: 37 | F11: kW | G11: 380 | H11: 71 | I11: 50 | J11: 6 | K11: 984 | L11: 6315 | M11: 6313 | N11: 250 | P11: 3 | S11: 55 | T11: F | V11: Delta | W11: Available | AE11: Internal | AF11: Horizontal
A12: =(EMO!A12) -> EMO000447 | B12: Rotorni | D12: XC | E12: 30 | F12: kW | G12: 380 | H12: 57 | I12: 50 | J12: 4 | K12: 1465 | N12: 200L | P12: 3 | S12: 55 | T12: F | V12: Delta | W12: Available | AE12: Internal | AF12: Vertical
A13: =(EMO!A13) -> EMO000382 | B13: ABB | D13: M2AA | E13: 37 | F13: kW | G13: 380 | H13: 71 | I13: 50 | J13: 4 | K13: 1470 | L13: 6313 | M13: 6313 | N13: 225 | P13: 3 | S13: 55 | T13: F | V13: Delta | W13: Available | AE13: Internal | AF13: Horizontal
A14: =(EMO!A14) -> EMO000452 | B14: TECO | C14: 7504760021 | D14: AEEBKB | E14: 75 | F14: kW | G14: 380 | H14: 140 | I14: 50 | J14: 4 | K14: 1475 | L14: 6316 | M14: 6213 | P14: 3 | S14: 55 | T14: F | V14: Delta | W14: Available | AE14: Internal | AF14: Horizontal
A15: =(EMO!A15) -> EMO000453 | B15: ABB | C15: 36B4182500 | D15: M2BA | E15: 22 | F15: kW | G15: 380 | H15: 42 | I15: 50 | J15: 4 | K15: 1470 | L15: 6310 | M15: 6310 | N15: 180L | P15: 3 | Q15: 0.87 | S15: 55 | T15: F | V15: Delta | W15: Not Available | AE15: Internal | AF15: Horizontal
A16: =(EMO!A16) -> EMO000454 | B16: LEROY SOMER | C16: 16003743 | D16: LS | E16: 18.5 | F16: kW | G16: 380 | H16: 37 | I16: 50 | J16: 4 | K16: 1445 | L16: 6310 | M16: 6210 | N16: 180 | P16: 3 | S16: 55 | T16: F | V16: Delta | W16: Not Available | AE16: Internal | AF16: Horizontal
A17: =(EMO!A17) -> EMO000455 | B17: TECO | C17: 9K60029 | D17: AEEBKB | E17: 15 | F17: kW | G17: 380 | H17: 31.9 | I17: 50 | J17: 6 | K17: 960 | L17: 6311 | M17: 6310 | N17: 180L | P17: 3 | S17: 50 | T17: F | V17: Delta | W17: Not Available | AE17: Internal | AF17: Horizontal
A18: =(EMO!A18) -> EMO000456 | B18: Huada | C18: 597205011 | D18: Y2 | E18: 37 | F18: kW | G18: 380 | H18: 69.9 | I18: 50 | J18: 4 | K18: 1475 | L18: -- | M18: -- | N18: 225S | P18: 3 | Q18: 0.87 | S18: 50 | T18: F | V18: Delta | W18: Not Available | AE18: Internal | AF18: Horizontal
A19: =(EMO!A19) -> EMO000458 | B19: ABB | C19: MK171008-AD | D19: MBT | E19: 30 | F19: kW | G19: 380 | H19: 61 | I19: 50 | J19: 4 | K19: 1475 | N19: 200L | P19: 3 | S19: 55 | T19: F | V19: Delta | W19: Available | AE19: Internal | AF19: Horizontal
A20: =(EMO!A20) -> EMO000459 | B20: ABB | C20: 00 405 | D20: MBT | E20: 15 | F20: kW | G20: 380 | H20: 30 | I20: 50 | J20: 4 | K20: 1450 | L20: 6209 | M20: 6209 | N20: 160L | O20: 42 | P20: 3 | S20: 55 | T20: F | V20: Delta | W20: Not Available | AA20: 254 | AB20: 254 | AC20: 160 | AE20: Internal | AF20: Horizontal
A21: =(EMO!A21) -> EMO000460 | B21: ABB | D21: MBT | E21: 15 | F21: kW | G21: 380 | H21: 30 | I21: 50 | J21: 4 | K21: 1470 | P21: 3 | S21: 55 | T21: F | V21: Star | W21: Not Available | AE21: Internal | AF21: Horizontal
A22: =(EMO!A22) -> EMO003501 | B22: ABB | C22: 3222176 | D22: M2BA | E22: 90 | F22: kW | G22: 380 | H22: 169 | I22: 50 | J22: 6 | K22: 989 | L22: 6319 | M22: 6316 | N22: 315SMB | P22: 3 | S22: 55 | T22: F | V22: Delta | W22: Available | AE22: Internal | AF22: Horizontal
A23: =(EMO!A23) -> EMO000462 | B23: ABB | C23: 00 445 | D23: MBT | E23: 22 | F23: kW | G23: 380 | H23: 44 | I23: 50 | J23: 4 | K23: 1470 | L23: 6211 | M23: 6210 | N23: 180L | O23: 48 | P23: 3 | S23: 55 | T23: F | V23: Delta | W23: Not Available | AA23: 241/279 | AB23: 279 | AC23: 180 | AE23: Internal | AF23: Horizontal
A24: =(EMO!A24) -> EMO002103 | B24: ABB | C24: 7474416 | D24: MBV 280S | E24: 75 | F24: kW | G24: 380 | H24: 145 | I24: 50 | J24: 4 | K24: 1480 | N24: 280 | P24: 3 | Q24: 0.85 | S24: 54 | T24: F | V24: Delta | W24: Available | AE24: Internal | AF24: Horizontal
A25: =(EMO!A25) -> EMO000464 | B25: ABB | C25: 462 | D25: MBT | E25: 18.5 | F25: kW | G25: 380 | H25: 39 | I25: 50 | J25: 4 | K25: 1470 | N25: 160L | P25: 3 | S25: 55 | T25: F | V25: Delta | W25: Not Available | AE25: Internal | AF25: Horizontal
A26: =(EMO!A26) -> EMO001060 | B26: TECO | D26: AEEB | E26: 15 | F26: kW | G26: 380 | H26: 29.4 | I26: 50 | J26: 4 | K26: 1455 | L26: 6309 | M26: 6307 | N26: 160M | P26: 3 | S26: 55 | T26: F | V26: Delta | W26: Not Available | AE26: Internal | AF26: Horizontal
A27: =(EMO!A27) -> EMO000467 | B27: ABB | C27: MK161005-AD | D27: MBT | E27: 15 | F27: kW | G27: 380 | H27: 30 | I27: 50 | J27: 4 | K27: 1460 | N27: 160L | P27: 3 | S27: 55 | T27: F | V27: Delta | W27: Not Available | AE27: Internal | AF27: Horizontal
A28: =(EMO!A28) -> EMO000468 | B28: TECO | C28: MN60170-1 | D28: AEEBWA | E28: 22 | F28: kW | G28: 380 | H28: 45.9 | I28: 50 | J28: 6 | K28: 965 | L28: 6312 | M28: 6212 | N28: 200L | P28: 3 | S28: 55 | T28: F | V28: Delta | W28: Available | AE28: Internal | AF28: Horizontal
A29: =(EMO!A29) -> EMO000469 | B29: CGE | C29: 273954062 | D29: C225S | E29: 37 | F29: kW | G29: 380 | H29: 70 | I29: 50 | J29: 4 | K29: 1470 | N29: 225S | P29: 3 | S29: 55 | T29: F | V29: Delta | W29: Available | AE29: Internal | AF29: Horizontal
A30: =(EMO!A30) -> EMO000470 | B30: TECO | C30: 9060002 | D30: AEEBAC | E30: 55 | F30: kW | G30: 380 | H30: 108 | I30: 50 | J30: 6 | K30: 970 | L30: NU218 | M30: 6214 | N30: 280SC | P30: 3 | S30: 55 | T30: F | V30: Delta | W30: Available | AE30: Internal | AF30: Horizontal
A31: =(EMO!A31) -> EMO000471 | B31: ASGEN | C31: 616357 | D31: 280M | E31: 55 | F31: kW | G31: 380 | H31: 108 | I31: 50 | J31: 6 | K31: 960 | N31: 280SC | P31: 3 | S31: 55 | T31: F | V31: Delta | W31: Available | AE31: Internal | AF31: Horizontal
A32: =(EMO!A32) -> EMO000472 | B32: XDJ | C32: 911038 | D32: C225S | E32: 37 | F32: kW | G32: 380 | H32: 70.4 | I32: 50 | J32: 4 | K32: 1480 | L32: 6313 | M32: 6313 | N32: 225 | P32: 3 | S32: 44 | T32: B | V32: Delta | W32: Available | AE32: Internal | AF32: Horizontal
A33: =(EMO!A33) -> EMO002949 | B33: ABB | C33: MK4281636-A | D33: HXR | E33: 45 | F33: kW | G33: 380 | H33: 86 | I33: 50 | J33: 6 | K33: 986 | L33: 6316 | M33: 6315 | N33: 280S | P33: 3 | S33: 55 | T33: F | V33: Delta | W33: Available | AE33: Internal | AF33: Horizontal
A34: =(EMO!A34) -> EMO000474 | B34: TECO | C34: 9060003 | D34: AEEBAC | E34: 55 | F34: kW | G34: 380 | H34: 108 | I34: 50 | J34: 6 | K34: 970 | L34: NU219 | M34: 6213 | N34: 280S | P34: 3 | S34: 55 | T34: F | V34: Delta | W34: Available | AE34: Internal | AF34: Horizontal
A35: =(EMO!A35) -> EMO000476 | B35: ABB | C35: 1701007-AP | D35: MBT | E35: 22 | F35: kW | G35: 380 | H35: 44 | I35: 50 | J35: 4 | K35: 1470 | N35: 180L | P35: 3 | S35: 55 | T35: F | V35: Delta | W35: Not Available | AE35: Internal | AF35: Horizontal
A36: =(EMO!A36) -> EMO000545 | B36: ROTOR-ni | C36: 730494-3 | D36: XF200L | E36: 22 | F36: kW | G36: 380 | H36: 44.5 | I36: 50 | J36: 6 | K36: 970 | N36: 200L | P36: 3 | S36: 55 | T36: F | V36: Delta | W36: Available | AE36: Internal | AF36: Horizontal
A37: =(EMO!A37) -> EMO000481 | B37: TECO | C37: K96068907 | D37: AEEBCB | E37: 37 | F37: kW | G37: 380 | H37: 70.9 | I37: 50 | J37: 4 | K37: 1455 | L37: 6313 | M37: 6213 | N37: 225 | P37: 3 | S37: 54 | T37: F | U37: S1 | V37: Delta | W37: Available | AC37: 225 | AE37: Internal | AF37: Horizontal
A38: =(EMO!A38) -> EMO000105 | B38: ABB | D38: MBT | E38: 7.5 | F38: kW | G38: 380 | H38: 16 | I38: 50 | J38: 4 | K38: 1470 | L38: 6208 | M38: 6206 | N38: 132M | P38: 3 | S38: 55 | T38: F | V38: Delta | W38: Not Available | AE38: Internal | AF38: Horizontal
A39: =(EMO!A39) -> EMO000487 | B39: FUJI ELECTRIK | C39: 1520911001415 | D39: MLA | E39: 7.5 | F39: kW | G39: 380 | H39: 15 | I39: 50 | J39: 4 | K39: 1460 | L39: 6308 | M39: 6209 | N39: 150M | P39: 3 | S39: 44 | T39: B | V39: Delta | W39: Not Available | AE39: Internal | AF39: Horizontal
A40: =(EMO!A40) -> EMO003727 | B40: ABB | C40: 4439VM | D40: HXA | E40: 7.5 | F40: kW | G40: 380 | H40: 16.3 | I40: 50 | J40: 4 | K40: 1440 | L40: 6308 | M40: 6307 | N40: 132 | O40: 38 | P40: 3 | Q40: 0.82 | S40: 55 | T40: F | U40: S1 | V40: Delta | W40: Available | AE40: Internal | AF40: Vertical
...

Sheet Sheet1
A1: equipment_type
A2: EMO
A3: MGM
A4: MGB
A5: MFB
A6: MDO

Sheet Sheet2
A1: id | B1: emo
A2: =LEN(B2)>9 -> FALSE | B2: EMO000256
A3: =LEN(B3)>9 -> FALSE | B3: EMO000257
A4: =LEN(B4)>9 -> FALSE | B4: EMO000258
A5: =LEN(B5)>9 -> FALSE | B5: EMO000259
A6: =LEN(B6)>9 -> TRUE | B6: EMO0000236
A7: =LEN(B7)>9 -> FALSE | B7: EMO000260
A8: =LEN(B8)>9 -> FALSE | B8: EMO000261
A9: =LEN(B9)>9 -> FALSE | B9: EMO000262
A10: =LEN(B10)>9 -> FALSE | B10: EMO000263
A11: =LEN(B11)>9 -> FALSE | B11: EMO000236
A12: =LEN(B12)>9 -> FALSE | B12: EMO000237
A13: =LEN(B13)>9 -> FALSE | B13: EMO000238
... A24: =LEN(B24)>9 -> FALSE | B24: EMO000248
